Workbook

Sheet 0_AI_to_EV_Bridge
B1: AI to EV bridge
B2: One bridge, from the enterprise value you have today to the enterprise value the AI program can carry. Everything is pulled from the tabs behind it — only the two yellow cells are entered here.
B5: INPUTS
B6: ENTER: Basis at entry | C6: ARR | E6: How the deal was struck, not a judgement about today. The basis is fixed for the whole model so before and after stay comparable. Anaplan entered at 18.1x revenue in 2022 while loss-making.
B7: ENTER: Enterprise value today | C7: 11000000000 | E7: Your own valuation, or the entry basis.
B8: ENTER: ARR | C8: 1200000000 | E8: Recurring revenue.
B9: Total revenue | C9: ='4b_Value_Pools_by_Capability'!$D$6 -> 1500000000 | E9: ARR plus professional services. Set on 4b.
B10: ENTER: EBITDA margin on total revenue | C10: 0.42 | E10: Carried for reference and for the Rule of 40 on 4d. Not used in the multiple while the basis is ARR. Verify before quoting.
B11: Valuation metric | C11: =IF($C$6="EBITDA",$C$9*$C$10,$C$8) -> 1200000000 | E11: EBITDA if the basis is EBITDA, ARR if it is ARR.
B12: Current multiple | C12: =IFERROR($C$7/$C$11,0) -> 9.1666667 | E12: Enterprise value divided by the metric. The anchor every scenario works from.
B13: Industry vertical | C13: ='4b_Value_Pools_by_Capability'!$D$4 -> Vertical SaaS | E13: Set on 4b.
B16: POSITION
B18: THE BRIDGE
B19: Closing two capability levels. Capturing the pool does two things: its revenue half lifts ARR, and the whole of it lifts growth, which lifts the multiple. Shown separately so the two effects are visible.
B21: Enterprise value today | C21: =$C$7 -> 11000000000 | E21: ARR $1.2B at 9.17x.
B22: plus ARR uplift | C22: =('8_Enterprise_Value'!$C$35-'8_Enterprise_Value'!$C$25)*'8_Enterprise_Value'!$D$33 -> 2.2130297e+08 | E22: The revenue half of the pool, valued at today’s multiple.
B23: plus multiple uplift | C23: ='8_Enterprise_Value'!$C$35*('8_Enterprise_Value'!$D$35-'8_Enterprise_Value'!$D$33) -> 2.9657974e+08 | E23: The multiple moving from 9.17x to 9.38x, on the new ARR base. | M23: New EV | P23: New EV
B24: less cost of the programme | C24: -16295149 | E24: NPV of build plus operating cost, Barr Eq. 26. | M24: =$C$26 -> 0 | P24: =$C$26 -> 0
B25: NEW ENTERPRISE VALUE | C25: =SUM($C$21:$C$24) -> 1.1501588e+10 | E25: ARR $1.22B at 9.38x, less cost.
B27: Uplift on today | C27: =IFERROR(($C$25-$C$21)/$C$21,0) -> 0.045598869
B28: Value density | C28: ='8_Enterprise_Value'!$C$38 -> 30.781404
B29: Check: ties to 8_Enterprise_Value | C29: =IF(ROUND($C$25,0)=ROUND('8_Enterprise_Value'!$E$35-'8_Enterprise_Value'!$C$29,0),"Ties","CHECK") -> Ties
B39: Chart data — calculated, do not edit
C40: Base | D40: Value
B41: EV today | C41: 0 | D41: =$C$21 -> 11000000000
B42: ARR uplift | C42: =$C$21 -> 11000000000 | D42: =$C$22 -> 2.2130297e+08
B43: Multiple uplift | C43: =$C$21+$C$22 -> 1.1221303e+10 | D43: =$C$23 -> 2.9657974e+08
B44: Cost | C44: =$C$25 -> 1.1501588e+10 | D44: =-$C$24 -> 16295149
B45: New EV | C45: 0 | D45: =$C$25 -> 1.1501588e+10
B47: The vertical axis starts at $10.4B. The two middle bars are about 2% of an $11B base — on a full axis they would not be visible. The base is the story here, not the bridge.

Sheet 1_Industry_Rubric
B2: Frontier rubric AI-enabled applications
B3: The benchmark is the cohort commanding the highest multiples in software, not other SaaS companies. Six dimensions define it. The ceiling on each is what a named company has actually achieved, not a theoretical maximum.
B5: Company | C5: Valuation | D5: ARR | E5: Multiple | F5: Pricing model | G5: What it displaces
B6: Sierra | C6: $10B | D6: ~$100M | E6: 67-100x | F6: Outcome, per resolution | G6: Support agent salary
B7: Harvey | C7: $11B | D7: ~$190M | E7: 55-58x | F7: Seat and licence | G7: Junior associate at $200/hr
B8: Cursor (Anysphere) | C8: $29-50B | D8: $0.5-2B | E8: 25-59x | F8: Seat | G8: Developer time
B9: Glean | C9: $7.2B | D9: $300M | E9: 24x | F9: Seat | G9: Knowledge worker search time
B10: Decagon | C10: $4.5B | D10: ~$35M | E10: high, 200%+ NRR | F10: Outcome | G10: Support agent salary
B11: Growth rate does not explain the spread — the fastest grower priced near the bottom. The premium tracks category position. Harvey trades at 55-58x on seat pricing, which is why outcome pricing is one route to the frontier and not the test itself.
B13: The six dimensions
B14: Code | C14: Dimension | D14: What it asks | E14: Frontier | F14: Held by | G14: Why not 10
B15: BD | C15: Budget Displaced | D15: Does your revenue come out of a labour line or a software line. | E15: 10 | F15: Harvey, Sierra, Cursor | G15: Full marks. Harvey's stated competitor is a junior associate at $200 an hour; Sierra's is a support agent; Cursor's is developer time. None of them competes for a software budget. This is what displacing a labour budget looks like — there is nothing further to reach.
B16: OA | C16: Outcome Attribution | D16: Can the value delivered be measured, isolated and agreed with the customer in advance. | E16: 9 | F16: Sierra, Fin | G16: Sierra bills on a resolved conversation and does not charge when unresolved; Fin publishes $0.99 per resolution. Held just below full marks because the outcome definition is still negotiated per contract and edge cases are contested deal by deal.
B17: AUT | C17: Autonomy | D17: How much of the work completes without a person, and what the person is for. | E17: 9.5 | F17: Sierra, Harvey | G17: Sierra agents process returns and manage cancellations through API connections to systems of record; Harvey customers run more than 25,000 custom agents. Held marginally below full marks because escalation to humans remains routine and is priced for.
B18: DC | C18: Data Compounding | D18: Does the product improve from usage in a way a competitor with the same models cannot replicate. | E18: 9 | F18: Harvey, Glean | G18: Vertical-specific agents with proprietary training data command the highest valuations in the cohort. Harvey holds legal workflow depth across most of the AmLaw 100. Held below full marks because the underlying models are third-party and commoditising, which is the standing bear case.
B19: VEL | C19: Velocity to Scale | D19: How fast the business reaches scale, which is what the market is actually pricing. | E19: 10 | F19: Cursor, Legora | G19: Full marks. Cursor reached $100M ARR in roughly 12 months, Legora in 18, against 36 for Slack. This is the fastest scaling enterprise software has produced.
B20: DE | C20: Delivery Elasticity | D20: Does serving more customers or more volume require proportionally more people. | E20: 8.5 | F20: Fin, Glean | G20: Fin deploys in days with published pricing and no platform fee. Held furthest below full marks because inference is real cost of goods — 18-23% of revenue — and AI gross margins run 50-60% against 70-90% for mature software. Nobody in the cohort has achieved elastic delivery.
C21: FRONTIER POSITION | E21: =AVERAGE(E15:E20) -> 9.3333333
B23: Level anchors by capability
B24: Seventy-two sets of five. Ten value levers and two enablers across the six dimensions. Wording is written per lever — no two blocks repeat.
B26: Capability | C26: Dimension | D26: L1 Laggard | E26: L2 Follower | F26: L3 Practitioner | G26: L4 Leader | H26: L5 Frontier
B27: Product and services differentiation | C27: Budget Displaced | D27: Priced against competing software. The buyer's alternative is another licence. | E27: Priced against software, with a productivity claim attached to justify the premium. | F27: Priced against software but the business case cites a headcount number. | G27: Priced against a named labour line, with the customer's cost per unit of that work known. | H27: The buyer's alternative is hiring. You are compared to a salary, not to a licence.
C28: Outcome Attribution | D28: What the product delivers is asserted in marketing and argued at renewal. | E28: You report adoption and usage to customers, not the value produced. | F28: You report outcomes, but cannot separate your contribution from everything else the customer did. | G28: Baselines are agreed with the customer before deployment and the delta withstands challenge. | H28: The outcome is machine-verifiable and published, not negotiated per contract.
C29: Autonomy | D29: The product records work a person at the customer does. | E29: The product suggests; a customer employee decides and executes every time. | F29: The product executes defined tasks; a customer employee approves before anything commits. | G29: The product completes whole customer workflows end to end, acting in systems of record. | H29: The product runs long-horizon, multi-step processes and escalates only by exception.
C30: Data Compounding | D30: Customer data sits in per-tenant silos. Nothing improves from usage. | E30: Usage is logged but never fed back into the product. | F30: Aggregate usage informs the roadmap, not the product's behaviour. | G30: Usage improves product behaviour across the base, with contractual rights in place to permit it. | H30: The corpus is the moat. A competitor with the same models cannot match the output.
C31: Velocity to Scale | D31: Flat, or too small to measure. | E31: Growing, but slower than the rest of the business. | F31: Growing faster than the rest of the business. | G31: Doubling annually off a base large enough to matter. | H31: The fastest-growing line in the company, and disclosed as such.
C32: Delivery Elasticity | D32: Every new customer needs a services engagement before the product produces anything. | E32: Onboarding is templated but still requires your people. | F32: Standard customers self-configure; your people handle the complex ones. | G32: Most customers reach value in days without your involvement. | H32: The marginal cost of the next customer is compute. No implementation function exists.
B33: Pricing and packaging | C33: Budget Displaced | D33: Priced per seat. Tiers are defined by feature count. | E33: Per seat, with usage add-ons bolted on to capture heavy users. | F33: A hybrid: platform fee plus a usage or volume component the customer can forecast. | G33: Priced on a value metric the customer already measures in their own P&L. | H33: Priced per outcome delivered. Seats are irrelevant to the contract.
C34: Outcome Attribution | D34: No outcome measurement. Discounting is unmanaged and realised price is discovered after the fact. | E34: Outcomes are claimed in marketing; realised price is tracked quarterly. | F34: Outcomes are reported to customers and discount approval follows a policy. | G34: Baselines are agreed before deployment and realised price holds within a narrow band of list. | H34: Outcome measurement is contractual and audited, and price realisation is designed into the metric rather than defended.
C35: Autonomy | D35: Every price is set by a person in a spreadsheet. | E35: Rate cards exist; exceptions are negotiated individually. | F35: Pricing rules are encoded and most quotes follow them. | G35: Price is set by the system from the value metric; humans handle exceptions. | H35: Pricing adjusts continuously to measured value and usage without a person in the loop.
C36: Data Compounding | D36: No record of what customers paid or why. | E36: Pricing history is stored but never analysed. | F36: Win-loss by price point is reviewed periodically. | G36: Realised price and churn data automatically re-tune the rate card. | H36: The pricing corpus is an advantage no competitor can see or replicate.
C37: Velocity to Scale | D37: Pricing changes take a year and a reorganisation. | E37: Changes ship annually, applied to new business only. | F37: Changes reach new business within a quarter. | G37: A new pricing model reaches the whole base within a renewal cycle. | H37: Pricing experiments run continuously across segments at no delivery cost.
C38: Delivery Elasticity | D38: Every non-standard deal needs finance to build a model. | E38: Templates exist but complex deals still consume finance time. | F38: Standard structures self-serve; finance handles the complex minority. | G38: Deal volume can double without adding pricing or finance headcount. | H38: The marginal cost of quoting the next deal is compute.
B39: Sales effectiveness | C39: Budget Displaced | D39: AI tooling is added to the sales stack. Selling capacity is unchanged. | E39: Reps report time saved, but the sales payroll has not moved. | F39: Freed selling time is reinvested in more activity rather than fewer sellers. | G39: Quota coverage has been achieved with fewer sellers than the plan called for. | H39: Selling capacity is set by compute, not by the number of sellers.
C40: Outcome Attribution | D40: Pipeline is attributed to reps by convention. No system contribution is measured. | E40: System usage is measured; its effect on pipeline is not. | F40: System-sourced pipeline is tracked but confounded with rep effort. | G40: System-sourced and rep-sourced pipeline are separated and the split withstands scrutiny. | H40: Contribution per system action is measured and reported continuously.
C41: Autonomy | D41: Reps research, write and follow up manually. | E41: AI drafts outreach and summarises calls; the rep does everything else. | F41: The system prioritises and sequences; a rep approves before anything sends. | G41: Agents run qualification and multi-threaded follow-up without a rep in the loop. | H41: The motion runs unattended to a qualified opportunity and escalates by exception.
C42: Data Compounding | D42: Billing and usage data is not analysed. | E42: Data is reported but never changes pricing. | F42: Pricing is reviewed periodically using historical data. | G42: Billing and usage data automatically improves pricing and packaging decisions. | H42: The pricing and usage record is an asset a competitor could not assemble.
C43: Velocity to Scale | D43: Quote-to-cash cycle time is unchanged or lengthening. | E43: Cycle time falling by a few percent a year. | F43: Cycle time falling by double digits a year. | G43: Cycle time has halved on a multi-year view. | H43: Billing and collection run in near real time.
C44: Delivery Elasticity | D44: Quote-to-cash headcount rises one for one with transaction volume. | E44: Some leverage, but headcount still tracks volume closely. | F44: Headcount grows at roughly half the rate of volume. | G44: Volume can double with little or no added headcount. | H44: The marginal cost of an additional transaction is compute, not people.
B45: Customer retention and expansion | C45: Budget Displaced | D45: Service is a cost you absorb. It appears in no customer business case. | E45: Service quality is a selling point, but nothing in the customer's budget moves because of it. | F45: The customer's business case counts service hours saved on their side. | G45: The customer has retired support headcount because of what you deliver. | H45: You are paid for resolutions the customer would otherwise have staffed.
...

Sheet 2_Capability_Assessment
AB1: level map
B2: Capability assessment | AB2: L1 | AC2: 0.2
B3: 36 capabilities across ten value levers. Each carries one rating; its frontier dimension is fixed. Read across the five descriptions and pick what the company can evidence today. Levels 4 and 5 need evidence a third party could verify — without it, score 3. Lever scores roll up on the machine block below and feed 4b. | AB3: L2 | AC3: 0.4
AB4: L3 | AC4: 0.6
B5: Lever | C5: Capability | D5: Dim | E5: L1 Absent | F5: L2 Emerging | G5: L3 Defined | H5: L4 Advanced | I5: L5 Frontier | J5: LEVEL | K5: Ceiling | L5: Metric impacted | M5: wt | N5: lvl# | O5: pts | AB5: L4 | AC5: 0.8
B6: Product and services differentiation | C6: Proprietary data advantage | D6: DC | E6: No usage or outcome data is retained beyond logs. | F6: Data is retained but sits in systems nobody queries. | G6: A usable dataset exists; it informs roadmap decisions periodically. | H6: The dataset measurably improves the product and a competitor could not assemble it quickly. | I6: The dataset is the product's core defence. Replicating it requires the same install base and the same years. | J6: L3 | K6: =IFERROR(INDEX('1_Industry_Rubric'!$E$15:$E$20,MATCH($D6,{"BD","OA","AUT","DC","VEL","DE"},0)),"") -> 9 | L6: Gross margin, NRR | M6: =IFERROR(INDEX('1_Industry_Rubric'!$C$101:$H$110,MATCH($B6,'1_Industry_Rubric'!$B$101:$B$110,0),MATCH($D6,{"BD","OA","AUT","DC","VEL","DE"},0)),"") -> 0.2 | N6: =IFERROR(VLOOKUP($J6,$AB$2:$AC$6,2,FALSE()),"") -> 0.6 | O6: =IFERROR($K6*$M6*$N6,"") -> 1.08 | AB6: L5 | AC6: 1
B7: Product and services differentiation | C7: AI-native product architecture | D7: AUT | E7: AI is absent, or bolted on as a separate feature. | F7: AI features exist alongside the core product but share no architecture with it. | G7: Core functions are exposed as callable actions; some agents operate on them. | H7: The product is API-first end to end; agents can execute any core function without touching the UI. | I7: The product was rebuilt around agent execution. The UI is one client among several. | J7: L4 | K7: =IFERROR(INDEX('1_Industry_Rubric'!$E$15:$E$20,MATCH($D7,{"BD","OA","AUT","DC","VEL","DE"},0)),"") -> 9.5 | L7: Gross margin, ARR growth | M7: =IFERROR(INDEX('1_Industry_Rubric'!$C$101:$H$110,MATCH($B7,'1_Industry_Rubric'!$B$101:$B$110,0),MATCH($D7,{"BD","OA","AUT","DC","VEL","DE"},0)),"") -> 0.15 | N7: =IFERROR(VLOOKUP($J7,$AB$2:$AC$6,2,FALSE()),"") -> 0.8 | O7: =IFERROR($K7*$M7*$N7,"") -> 1.14
B8: Product and services differentiation | C8: Workflow depth and embeddedness | D8: BD | E8: Used occasionally, easily replaced, no dependency. | F8: Used regularly but sits alongside the customer's real workflow. | G8: Embedded in a workflow the customer runs weekly. | H8: Embedded in a workflow that would break if the product were removed. | I8: The customer's process was redesigned around the product. Removal means rehiring. | J8: L3 | K8: =IFERROR(INDEX('1_Industry_Rubric'!$E$15:$E$20,MATCH($D8,{"BD","OA","AUT","DC","VEL","DE"},0)),"") -> 10 | L8: GRR, NRR | M8: =IFERROR(INDEX('1_Industry_Rubric'!$C$101:$H$110,MATCH($B8,'1_Industry_Rubric'!$B$101:$B$110,0),MATCH($D8,{"BD","OA","AUT","DC","VEL","DE"},0)),"") -> 0.3 | N8: =IFERROR(VLOOKUP($J8,$AB$2:$AC$6,2,FALSE()),"") -> 0.6 | O8: =IFERROR($K8*$M8*$N8,"") -> 1.8
B9: Product and services differentiation | C9: Release velocity | D9: VEL | E9: Releases are irregular and each one is a project. | F9: Scheduled releases, but new functionality reaches customers slowly. | G9: Regular release cadence; most customers are within a version or two. | H9: New functionality reaches the whole install base within a release cycle. | I9: Continuous delivery to the whole install base at no incremental cost per customer. | J9: L3 | K9: =IFERROR(INDEX('1_Industry_Rubric'!$E$15:$E$20,MATCH($D9,{"BD","OA","AUT","DC","VEL","DE"},0)),"") -> 10 | L9: ARR growth, NRR | M9: =IFERROR(INDEX('1_Industry_Rubric'!$C$101:$H$110,MATCH($B9,'1_Industry_Rubric'!$B$101:$B$110,0),MATCH($D9,{"BD","OA","AUT","DC","VEL","DE"},0)),"") -> 0.15 | N9: =IFERROR(VLOOKUP($J9,$AB$2:$AC$6,2,FALSE()),"") -> 0.6 | O9: =IFERROR($K9*$M9*$N9,"") -> 0.9
B10: Product and services differentiation | C10: Model portability | D10: DE | E10: Built against one provider's API. Swapping means a rewrite. | F10: One provider, but calls are wrapped behind an internal interface. | G10: An abstraction layer exists; a second provider has been tested but not run in production. | H10: Two or more providers run in production and traffic can be shifted without a release. | I10: Requests route by cost and task across providers automatically. No single provider has pricing leverage over you. | J10: L2 | K10: =IFERROR(INDEX('1_Industry_Rubric'!$E$15:$E$20,MATCH($D10,{"BD","OA","AUT","DC","VEL","DE"},0)),"") -> 8.5 | L10: Gross margin, COGS per transaction | M10: =IFERROR(INDEX('1_Industry_Rubric'!$C$101:$H$110,MATCH($B10,'1_Industry_Rubric'!$B$101:$B$110,0),MATCH($D10,{"BD","OA","AUT","DC","VEL","DE"},0)),"") -> 0.05 | N10: =IFERROR(VLOOKUP($J10,$AB$2:$AC$6,2,FALSE()),"") -> 0.4 | O10: =IFERROR($K10*$M10*$N10,"") -> 0.17
B11: Pricing and packaging | C11: Value metric and packaging design | D11: BD | E11: Priced per seat, with tiers defined by feature count. | F11: Per seat with usage add-ons bolted on top. | G11: A hybrid exists: platform fee plus a usage or volume component. | H11: Priced on a value metric the customer already measures in their own P&L. | I11: Priced per outcome delivered. Seats are irrelevant to the contract. | J11: L3 | K11: =IFERROR(INDEX('1_Industry_Rubric'!$E$15:$E$20,MATCH($D11,{"BD","OA","AUT","DC","VEL","DE"},0)),"") -> 10 | L11: ASP, NRR | M11: =IFERROR(INDEX('1_Industry_Rubric'!$C$101:$H$110,MATCH($B11,'1_Industry_Rubric'!$B$101:$B$110,0),MATCH($D11,{"BD","OA","AUT","DC","VEL","DE"},0)),"") -> 0.35 | N11: =IFERROR(VLOOKUP($J11,$AB$2:$AC$6,2,FALSE()),"") -> 0.6 | O11: =IFERROR($K11*$M11*$N11,"") -> 2.1
B12: Pricing and packaging | C12: Outcome measurement and price realisation | D12: OA | E12: No outcome measurement. Discounting is unmanaged. | F12: Outcomes are claimed in marketing; realised price is tracked after the fact. | G12: Outcomes are reported to customers; discount approval has a policy. | H12: Baseline agreed before deployment and the delta measured against it; realised price holds within a narrow band of list. | I12: Outcome measurement is contractual and audited, and price realisation is designed into the metric rather than defended. | J12: L3 | K12: =IFERROR(INDEX('1_Industry_Rubric'!$E$15:$E$20,MATCH($D12,{"BD","OA","AUT","DC","VEL","DE"},0)),"") -> 9 | L12: Realised price, NRR | M12: =IFERROR(INDEX('1_Industry_Rubric'!$C$101:$H$110,MATCH($B12,'1_Industry_Rubric'!$B$101:$B$110,0),MATCH($D12,{"BD","OA","AUT","DC","VEL","DE"},0)),"") -> 0.35 | N12: =IFERROR(VLOOKUP($J12,$AB$2:$AC$6,2,FALSE()),"") -> 0.6 | O12: =IFERROR($K12*$M12*$N12,"") -> 1.89
B13: Sales effectiveness | C13: Buyer-value discovery | D13: BD | E13: Discovery covers requirements and features only. | F13: Discovery asks about pain but not about cost of the work. | G13: Reps ask what the current process costs, though the answer rarely reaches the proposal. | H13: Every enterprise deal is scoped against a quantified labour line the buyer confirms. | I13: The buyer's own finance team supplies the baseline. The deal is priced against their number, not yours. | J13: L4 | K13: =IFERROR(INDEX('1_Industry_Rubric'!$E$15:$E$20,MATCH($D13,{"BD","OA","AUT","DC","VEL","DE"},0)),"") -> 10 | L13: Win rate, ASP | M13: =IFERROR(INDEX('1_Industry_Rubric'!$C$101:$H$110,MATCH($B13,'1_Industry_Rubric'!$B$101:$B$110,0),MATCH($D13,{"BD","OA","AUT","DC","VEL","DE"},0)),"") -> 0.15 | N13: =IFERROR(VLOOKUP($J13,$AB$2:$AC$6,2,FALSE()),"") -> 0.8 | O13: =IFERROR($K13*$M13*$N13,"") -> 1.2
B14: Sales effectiveness | C14: Pipeline intelligence | D14: DC | E14: Pipeline is whatever reps type into the CRM. | F14: Stage definitions exist; hygiene is enforced manually. | G14: Scoring exists and is roughly trusted; forecasts are still adjusted by judgement. | H14: Signals from product and engagement data drive scoring, and the model is measurably calibrated. | I14: Pipeline quality improves continuously from closed-loop outcome data no competitor holds. | J14: L3 | K14: =IFERROR(INDEX('1_Industry_Rubric'!$E$15:$E$20,MATCH($D14,{"BD","OA","AUT","DC","VEL","DE"},0)),"") -> 9 | L14: Forecast accuracy, win rate | M14: =IFERROR(INDEX('1_Industry_Rubric'!$C$101:$H$110,MATCH($B14,'1_Industry_Rubric'!$B$101:$B$110,0),MATCH($D14,{"BD","OA","AUT","DC","VEL","DE"},0)),"") -> 0.1 | N14: =IFERROR(VLOOKUP($J14,$AB$2:$AC$6,2,FALSE()),"") -> 0.6 | O14: =IFERROR($K14*$M14*$N14,"") -> 0.54
B15: Sales effectiveness | C15: Deal desk and approval design | D15: AUT | E15: Approvals are ad hoc, routed by email. | F15: A policy exists; exceptions are frequent and manual. | G15: Deal desk reviews non-standard terms within a defined SLA. | H15: Standard deals clear approval automatically; humans see exceptions only. | I15: Approval logic is encoded end to end. Terms outside policy cannot be quoted. | J15: L2 | K15: =IFERROR(INDEX('1_Industry_Rubric'!$E$15:$E$20,MATCH($D15,{"BD","OA","AUT","DC","VEL","DE"},0)),"") -> 9.5 | L15: Sales cycle time, discount leakage | M15: =IFERROR(INDEX('1_Industry_Rubric'!$C$101:$H$110,MATCH($B15,'1_Industry_Rubric'!$B$101:$B$110,0),MATCH($D15,{"BD","OA","AUT","DC","VEL","DE"},0)),"") -> 0.25 | N15: =IFERROR(VLOOKUP($J15,$AB$2:$AC$6,2,FALSE()),"") -> 0.4 | O15: =IFERROR($K15*$M15*$N15,"") -> 0.95
B16: Sales effectiveness | C16: Rep enablement and ramp | D16: DE | E16: New reps learn by shadowing. Ramp is undefined. | F16: Onboarding content exists but is static and rarely updated. | G16: Structured ramp with defined milestones; time to quota is measured. | H16: Enablement adapts to the rep, and ramp time has measurably shortened. | I16: Adding a rep costs a fraction of what it did two years ago, and quota attainment holds. | J16: L3 | K16: =IFERROR(INDEX('1_Industry_Rubric'!$E$15:$E$20,MATCH($D16,{"BD","OA","AUT","DC","VEL","DE"},0)),"") -> 8.5 | L16: Time to quota, sales efficiency | M16: =IFERROR(INDEX('1_Industry_Rubric'!$C$101:$H$110,MATCH($B16,'1_Industry_Rubric'!$B$101:$B$110,0),MATCH($D16,{"BD","OA","AUT","DC","VEL","DE"},0)),"") -> 0.1 | N16: =IFERROR(VLOOKUP($J16,$AB$2:$AC$6,2,FALSE()),"") -> 0.6 | O16: =IFERROR($K16*$M16*$N16,"") -> 0.51
B17: Sales effectiveness | C17: Sales methodology consistency | D17: VEL | E17: No common methodology. Every rep sells their own way. | F17: A methodology is named in training but not used in the CRM or in deal reviews. | G17: Methodology is applied in pre-sales; qualification fields are completed on most deals. | H17: The same methodology runs pre-sales and post-sales, and handover carries the qualification and the value case intact. | I17: One methodology governs discovery through renewal across the whole organisation, and every deal review uses its language. | J17: L3 | K17: =IFERROR(INDEX('1_Industry_Rubric'!$E$15:$E$20,MATCH($D17,{"BD","OA","AUT","DC","VEL","DE"},0)),"") -> 10 | L17: Win rate, forecast accuracy | M17: =IFERROR(INDEX('1_Industry_Rubric'!$C$101:$H$110,MATCH($B17,'1_Industry_Rubric'!$B$101:$B$110,0),MATCH($D17,{"BD","OA","AUT","DC","VEL","DE"},0)),"") -> 0.3 | N17: =IFERROR(VLOOKUP($J17,$AB$2:$AC$6,2,FALSE()),"") -> 0.6 | O17: =IFERROR($K17*$M17*$N17,"") -> 1.8
B18: Customer retention and expansion | C18: Health signal detection | D18: DC | E18: Churn is discovered at renewal. | F18: Usage is reported but not connected to renewal risk. | G18: A health score exists and is broadly believed. | H18: Risk is predicted early enough to act, and the prediction is measurably accurate. | I18: Detection improves continuously from every renewal outcome, across the whole base. | J18: L3 | K18: =IFERROR(INDEX('1_Industry_Rubric'!$E$15:$E$20,MATCH($D18,{"BD","OA","AUT","DC","VEL","DE"},0)),"") -> 9 | L18: GRR, churn rate | M18: =IFERROR(INDEX('1_Industry_Rubric'!$C$101:$H$110,MATCH($B18,'1_Industry_Rubric'!$B$101:$B$110,0),MATCH($D18,{"BD","OA","AUT","DC","VEL","DE"},0)),"") -> 0.2 | N18: =IFERROR(VLOOKUP($J18,$AB$2:$AC$6,2,FALSE()),"") -> 0.6 | O18: =IFERROR($K18*$M18*$N18,"") -> 1.08
... B41: Capital efficiency | C41: Burn discipline | D41: DE | E41: Burn is reported but not managed against a plan. | F41: A plan exists; variance is explained after the quarter. | G41: Burn is managed to plan with monthly accountability by owner. | H41: Growth is funded without a proportional increase in burn; Rule of 40 is measurably improving. | I41: The company can grow volume substantially without a material step in cost. | J41: L3 | K41: =IFERROR(INDEX('1_Industry_Rubric'!$E$15:$E$20,MATCH($D41,{"BD","OA","AUT","DC","VEL","DE"},0)),"") -> 8.5 | L41: Rule of 40, burn multiple | M41: =IFERROR(INDEX('1_Industry_Rubric'!$C$101:$H$110,MATCH($B41,'1_Industry_Rubric'!$B$101:$B$110,0),MATCH($D41,{"BD","OA","AUT","DC","VEL","DE"},0)),"") -> 0.25 | N41: =IFERROR(VLOOKUP($J41,$AB$2:$AC$6,2,FALSE()),"") -> 0.6 | O41: =IFERROR($K41*$M41*$N41,"") -> 1.275
B44: Machine block — lever rollup. Barr dimension weighting, normalised for the dimensions each lever actually touches.
B45: Lever | C45: Score | D45: Ceiling | E45: Gap | F45: % of frontier | G45: Capabilities
B46: Product and services differentiation | C46: =IFERROR(SUMIFS($O$6:$O$41,$B$6:$B$41,$B46)/SUMIFS($M$6:$M$41,$B$6:$B$41,$B46),"") -> 5.9882353 | D46: =IFERROR(VLOOKUP($B46,'1_Industry_Rubric'!$B$101:$J$110,9,FALSE()),"") -> 9.5 | E46: =IFERROR($D46-$C46,"") -> 3.5117647 | F46: =IFERROR($C46/$D46,"") -> 0.63034056 | G46: =COUNTIFS($B$6:$B$41,$B46) -> 5
B47: Pricing and packaging | C47: =IFERROR(SUMIFS($O$6:$O$41,$B$6:$B$41,$B47)/SUMIFS($M$6:$M$41,$B$6:$B$41,$B47),"") -> 5.7 | D47: =IFERROR(VLOOKUP($B47,'1_Industry_Rubric'!$B$101:$J$110,9,FALSE()),"") -> 9.45 | E47: =IFERROR($D47-$C47,"") -> 3.75 | F47: =IFERROR($C47/$D47,"") -> 0.6031746 | G47: =COUNTIFS($B$6:$B$41,$B47) -> 2
B48: Sales effectiveness | C48: =IFERROR(SUMIFS($O$6:$O$41,$B$6:$B$41,$B48)/SUMIFS($M$6:$M$41,$B$6:$B$41,$B48),"") -> 5.5555556 | D48: =IFERROR(VLOOKUP($B48,'1_Industry_Rubric'!$B$101:$J$110,9,FALSE()),"") -> 9.525 | E48: =IFERROR($D48-$C48,"") -> 3.9694444 | F48: =IFERROR($C48/$D48,"") -> 0.58326043 | G48: =COUNTIFS($B$6:$B$41,$B48) -> 5
B49: Customer retention and expansion | C49: =IFERROR(SUMIFS($O$6:$O$41,$B$6:$B$41,$B49)/SUMIFS($M$6:$M$41,$B$6:$B$41,$B49),"") -> 6.0352941 | D49: =IFERROR(VLOOKUP($B49,'1_Industry_Rubric'!$B$101:$J$110,9,FALSE()),"") -> 9.2 | E49: =IFERROR($D49-$C49,"") -> 3.1647059 | F49: =IFERROR($C49/$D49,"") -> 0.65601023 | G49: =COUNTIFS($B$6:$B$41,$B49) -> 4
B50: Ecosystem strategy | C50: =IFERROR(SUMIFS($O$6:$O$41,$B$6:$B$41,$B50)/SUMIFS($M$6:$M$41,$B$6:$B$41,$B50),"") -> 5.2769231 | D50: =IFERROR(VLOOKUP($B50,'1_Industry_Rubric'!$B$101:$J$110,9,FALSE()),"") -> 9.325 | E50: =IFERROR($D50-$C50,"") -> 4.0480769 | F50: =IFERROR($C50/$D50,"") -> 0.56588987 | G50: =COUNTIFS($B$6:$B$41,$B50) -> 3
B51: Product engineering | C51: =IFERROR(SUMIFS($O$6:$O$41,$B$6:$B$41,$B51)/SUMIFS($M$6:$M$41,$B$6:$B$41,$B51),"") -> 7.1529412 | D51: =IFERROR(VLOOKUP($B51,'1_Industry_Rubric'!$B$101:$J$110,9,FALSE()),"") -> 9.4 | E51: =IFERROR($D51-$C51,"") -> 2.2470588 | F51: =IFERROR($C51/$D51,"") -> 0.76095119 | G51: =COUNTIFS($B$6:$B$41,$B51) -> 4
B52: Revenue operations | C52: =IFERROR(SUMIFS($O$6:$O$41,$B$6:$B$41,$B52)/SUMIFS($M$6:$M$41,$B$6:$B$41,$B52),"") -> 6.0714286 | D52: =IFERROR(VLOOKUP($B52,'1_Industry_Rubric'!$B$101:$J$110,9,FALSE()),"") -> 9.3 | E52: =IFERROR($D52-$C52,"") -> 3.2285714 | F52: =IFERROR($C52/$D52,"") -> 0.65284178 | G52: =COUNTIFS($B$6:$B$41,$B52) -> 3
B53: Supplier and infrastructure cost | C53: =IFERROR(SUMIFS($O$6:$O$41,$B$6:$B$41,$B53)/SUMIFS($M$6:$M$41,$B$6:$B$41,$B53),"") -> 3.3866667 | D53: =IFERROR(VLOOKUP($B53,'1_Industry_Rubric'!$B$101:$J$110,9,FALSE()),"") -> 9.025 | E53: =IFERROR($D53-$C53,"") -> 5.6383333 | F53: =IFERROR($C53/$D53,"") -> 0.37525392 | G53: =COUNTIFS($B$6:$B$41,$B53) -> 3
B54: Employee experience | C54: =IFERROR(SUMIFS($O$6:$O$41,$B$6:$B$41,$B54)/SUMIFS($M$6:$M$41,$B$6:$B$41,$B54),"") -> 5.26875 | D54: =IFERROR(VLOOKUP($B54,'1_Industry_Rubric'!$B$101:$J$110,9,FALSE()),"") -> 9.225 | E54: =IFERROR($D54-$C54,"") -> 3.95625 | F54: =IFERROR($C54/$D54,"") -> 0.57113821 | G54: =COUNTIFS($B$6:$B$41,$B54) -> 4
B55: Capital efficiency | C55: =IFERROR(SUMIFS($O$6:$O$41,$B$6:$B$41,$B55)/SUMIFS($M$6:$M$41,$B$6:$B$41,$B55),"") -> 4.8357143 | D55: =IFERROR(VLOOKUP($B55,'1_Industry_Rubric'!$B$101:$J$110,9,FALSE()),"") -> 9.175 | E55: =IFERROR($D55-$C55,"") -> 4.3392857 | F55: =IFERROR($C55/$D55,"") -> 0.52705333 | G55: =COUNTIFS($B$6:$B$41,$B55) -> 3
B58: Frontier dimensions
B59: Dimension | C59: Mean level | D59: Ceiling | E59: Readiness
B60: BD | C60: =IFERROR(AVERAGEIFS($N$6:$N$41,$D$6:$D$41,"BD"),"") -> 0.56 | D60: ='1_Industry_Rubric'!$E$15 -> 10 | E60: =IFERROR($C60*$D60,"") -> 5.6
B61: OA | C61: =IFERROR(AVERAGEIFS($N$6:$N$41,$D$6:$D$41,"OA"),"") -> 0.64 | D61: ='1_Industry_Rubric'!$E$16 -> 9 | E61: =IFERROR($C61*$D61,"") -> 5.76
B62: AUT | C62: =IFERROR(AVERAGEIFS($N$6:$N$41,$D$6:$D$41,"AUT"),"") -> 0.6 | D62: ='1_Industry_Rubric'!$E$17 -> 9.5 | E62: =IFERROR($C62*$D62,"") -> 5.7
B63: DC | C63: =IFERROR(AVERAGEIFS($N$6:$N$41,$D$6:$D$41,"DC"),"") -> 0.63333333 | D63: ='1_Industry_Rubric'!$E$18 -> 9 | E63: =IFERROR($C63*$D63,"") -> 5.7
B64: VEL | C64: =IFERROR(AVERAGEIFS($N$6:$N$41,$D$6:$D$41,"VEL"),"") -> 0.6 | D64: ='1_Industry_Rubric'!$E$19 -> 10 | E64: =IFERROR($C64*$D64,"") -> 6
B65: DE | C65: =IFERROR(AVERAGEIFS($N$6:$N$41,$D$6:$D$41,"DE"),"") -> 0.6 | D65: ='1_Industry_Rubric'!$E$20 -> 8.5 | E65: =IFERROR($C65*$D65,"") -> 5.1
B68: Weighted capability score | C68: =IFERROR(SUM($O$6:$O$41)/SUM($M$6:$M$41),"") -> 5.5625806
...

Sheet 3_Distance_to_Frontier
B2: Distance to frontier
B3: Live from 2_Capability_Assessment. Distance is measured against each capability's own ceiling, derived from the six dimensions weighted for that capability. The value column is what closing the gap is worth before feasibility and timing.
B5: Value lever | C5: Score | D5: Ceiling | E5: Gap | F5: % of frontier | G5: Closed | H5: Reachable | I5: Gross pool | J5: Adjusted pool | K5: At stake
B6: ='2_Capability_Assessment'!$B$46 -> Product and services differentiation | C6: ='2_Capability_Assessment'!$C$46 -> 5.9882353 | D6: ='2_Capability_Assessment'!$D$46 -> 9.5 | E6: =IFERROR($D6-$C6,"") -> 3.5117647 | F6: =IFERROR($C6/$D6,"") -> 0.63034056 | G6: =IFERROR($C6/$D6,"") -> 0.63034056 | H6: =IFERROR('4b_Value_Pools_by_Capability'!$L$15,"") -> 0.72535895 | I6: =IFERROR('4b_Value_Pools_by_Capability'!$E$15,"") -> 187500000 | J6: =IFERROR('4b_Value_Pools_by_Capability'!$O$15,"") -> 21893199 | K6: =IFERROR($I6-$J6,"") -> 1.656068e+08
B7: ='2_Capability_Assessment'!$B$47 -> Pricing and packaging | C7: ='2_Capability_Assessment'!$C$47 -> 5.7 | D7: ='2_Capability_Assessment'!$D$47 -> 9.45 | E7: =IFERROR($D7-$C7,"") -> 3.75 | F7: =IFERROR($C7/$D7,"") -> 0.6031746 | G7: =IFERROR($C7/$D7,"") -> 0.6031746 | H7: =IFERROR('4b_Value_Pools_by_Capability'!$L$16,"") -> 0.72535895 | I7: =IFERROR('4b_Value_Pools_by_Capability'!$E$16,"") -> 1.0125e+08 | J7: =IFERROR('4b_Value_Pools_by_Capability'!$O$16,"") -> 7070511 | K7: =IFERROR($I7-$J7,"") -> 94179489
B8: ='2_Capability_Assessment'!$B$48 -> Sales effectiveness | C8: ='2_Capability_Assessment'!$C$48 -> 5.5555556 | D8: ='2_Capability_Assessment'!$D$48 -> 9.525 | E8: =IFERROR($D8-$C8,"") -> 3.9694444 | F8: =IFERROR($C8/$D8,"") -> 0.58326043 | G8: =IFERROR($C8/$D8,"") -> 0.58326043 | H8: =IFERROR('4b_Value_Pools_by_Capability'!$L$17,"") -> 0.72535895 | I8: =IFERROR('4b_Value_Pools_by_Capability'!$E$17,"") -> 41400000 | J8: =IFERROR('4b_Value_Pools_by_Capability'!$O$17,"") -> 3913844.9 | K8: =IFERROR($I8-$J8,"") -> 37486155
B9: ='2_Capability_Assessment'!$B$49 -> Customer retention and expansion | C9: ='2_Capability_Assessment'!$C$49 -> 6.0352941 | D9: ='2_Capability_Assessment'!$D$49 -> 9.2 | E9: =IFERROR($D9-$C9,"") -> 3.1647059 | F9: =IFERROR($C9/$D9,"") -> 0.65601023 | G9: =IFERROR($C9/$D9,"") -> 0.65601023 | H9: =IFERROR('4b_Value_Pools_by_Capability'!$L$18,"") -> 0.72535895 | I9: =IFERROR('4b_Value_Pools_by_Capability'!$E$18,"") -> 28500000 | J9: =IFERROR('4b_Value_Pools_by_Capability'!$O$18,"") -> 2597463.4 | K9: =IFERROR($I9-$J9,"") -> 25902537
B10: ='2_Capability_Assessment'!$B$50 -> Ecosystem strategy | C10: ='2_Capability_Assessment'!$C$50 -> 5.2769231 | D10: ='2_Capability_Assessment'!$D$50 -> 9.325 | E10: =IFERROR($D10-$C10,"") -> 4.0480769 | F10: =IFERROR($C10/$D10,"") -> 0.56588987 | G10: =IFERROR($C10/$D10,"") -> 0.56588987 | H10: =IFERROR('4b_Value_Pools_by_Capability'!$L$19,"") -> 0.72535895 | I10: =IFERROR('4b_Value_Pools_by_Capability'!$E$19,"") -> 9000000 | J10: =IFERROR('4b_Value_Pools_by_Capability'!$O$19,"") -> 530676.26 | K10: =IFERROR($I10-$J10,"") -> 8469323.7
B11: ='2_Capability_Assessment'!$B$51 -> Product engineering | C11: ='2_Capability_Assessment'!$C$51 -> 7.1529412 | D11: ='2_Capability_Assessment'!$D$51 -> 9.4 | E11: =IFERROR($D11-$C11,"") -> 2.2470588 | F11: =IFERROR($C11/$D11,"") -> 0.76095119 | G11: =IFERROR($C11/$D11,"") -> 0.76095119 | H11: =IFERROR('4b_Value_Pools_by_Capability'!$L$20,"") -> 0.72535895 | I11: =IFERROR('4b_Value_Pools_by_Capability'!$E$20,"") -> 68640000 | J11: =IFERROR('4b_Value_Pools_by_Capability'!$O$20,"") -> 10280062 | K11: =IFERROR($I11-$J11,"") -> 58359938
B12: ='2_Capability_Assessment'!$B$52 -> Revenue operations | C12: ='2_Capability_Assessment'!$C$52 -> 6.0714286 | D12: ='2_Capability_Assessment'!$D$52 -> 9.3 | E12: =IFERROR($D12-$C12,"") -> 3.2285714 | F12: =IFERROR($C12/$D12,"") -> 0.65284178 | G12: =IFERROR($C12/$D12,"") -> 0.65284178 | H12: =IFERROR('4b_Value_Pools_by_Capability'!$L$21,"") -> 0.72535895 | I12: =IFERROR('4b_Value_Pools_by_Capability'!$E$21,"") -> 10800000 | J12: =IFERROR('4b_Value_Pools_by_Capability'!$O$21,"") -> 1061176.9 | K12: =IFERROR($I12-$J12,"") -> 9738823.1
B13: ='2_Capability_Assessment'!$B$53 -> Supplier and infrastructure cost | C13: ='2_Capability_Assessment'!$C$53 -> 3.3866667 | D13: ='2_Capability_Assessment'!$D$53 -> 9.025 | E13: =IFERROR($D13-$C13,"") -> 5.6383333 | F13: =IFERROR($C13/$D13,"") -> 0.37525392 | G13: =IFERROR($C13/$D13,"") -> 0.37525392 | H13: =IFERROR('4b_Value_Pools_by_Capability'!$L$22,"") -> 0.72535895 | I13: =IFERROR('4b_Value_Pools_by_Capability'!$E$22,"") -> 16200000 | J13: =IFERROR('4b_Value_Pools_by_Capability'!$O$22,"") -> 281522.41 | K13: =IFERROR($I13-$J13,"") -> 15918478
B14: ='2_Capability_Assessment'!$B$54 -> Employee experience | C14: ='2_Capability_Assessment'!$C$54 -> 5.26875 | D14: ='2_Capability_Assessment'!$D$54 -> 9.225 | E14: =IFERROR($D14-$C14,"") -> 3.95625 | F14: =IFERROR($C14/$D14,"") -> 0.57113821 | G14: =IFERROR($C14/$D14,"") -> 0.57113821 | H14: =IFERROR('4b_Value_Pools_by_Capability'!$L$23,"") -> 0.72535895 | I14: =IFERROR('4b_Value_Pools_by_Capability'!$E$23,"") -> 21600000 | J14: =IFERROR('4b_Value_Pools_by_Capability'!$O$23,"") -> 1999565.9 | K14: =IFERROR($I14-$J14,"") -> 19600434
B15: ='2_Capability_Assessment'!$B$55 -> Capital efficiency | C15: ='2_Capability_Assessment'!$C$55 -> 4.8357143 | D15: ='2_Capability_Assessment'!$D$55 -> 9.175 | E15: =IFERROR($D15-$C15,"") -> 4.3392857 | F15: =IFERROR($C15/$D15,"") -> 0.52705333 | G15: =IFERROR($C15/$D15,"") -> 0.52705333 | H15: =IFERROR('4b_Value_Pools_by_Capability'!$L$24,"") -> 0.72535895 | I15: =IFERROR('4b_Value_Pools_by_Capability'!$E$24,"") -> 0 | J15: =IFERROR('4b_Value_Pools_by_Capability'!$O$24,"") -> 0 | K15: =IFERROR($I15-$J15,"") -> 0
B17: Binding dimension | C17: =IFERROR(INDEX('2_Capability_Assessment'!$B$60:$B$65,MATCH(MIN('2_Capability_Assessment'!$E$60:$E$65),'2_Capability_Assessment'!$E$60:$E$65,0)),"") -> DE
B19: Data foundation | C19: ='2_Capability_Assessment'!$C$80 -> 6.6666667 | D19: 10 | E19: =IFERROR($C19/$D19,0) -> 0.66666667 | F19: =IF($C19=0,"not scored",IF($C19<7,"CAPPING","clear")) -> CAPPING
B20: Governance & funding | C20: ='2_Capability_Assessment'!$C$81 -> 7.2 | D20: 10 | E20: =IFERROR($C20/$D20,0) -> 0.72 | F20: =IF($C20=0,"not scored",IF($C20<7,"CAPPING","clear")) -> clear
B21: Gate applied to capture | C21: ='2_Capability_Assessment'!$C$82 -> 0.95238095 | E21: Multiplies every capability's maturity on 4b. An enabler at or above 70% of the frontier does not cap; below that it suppresses capture proportionally.
B24: Closed is the share of the ceiling already reached. Reachable is Barr's gap scaling function eta(g), pulled from 4b — the further from the frontier, the more of the pool is still unclaimed, so reachability rises with distance and is floored at 15%. Read the two together: a capability that is far behind has more headroom but converts it less well, which is why readiness and reachability pull against each other. At stake is the gross pool less what is currently adjustable, which is what closing the capability gap is worth before feasibility and timing are applied.

Sheet 4b_Value_Pools_by_Capability
B1: Value pools by value lever
B2: The prize is set by the company’s own cost and revenue lines, not by its scores. For each lever: revenue × base % (the line it touches) × uplift % (a published benchmark for what AI does to that line) = GROSS. Only then do the scores apply, through capture ceiling, reachability and capability maturity = ADJUSTED.
B3: INPUTS
B4: Industry vertical | D4: Vertical SaaS | E4: Sets the frontier cohort. Read by tabs 5 and 6.
B5: Industry critical scale S* | D5: 3300000000 | E5: Barr’s critical-scale threshold. Drives the firm scale factor.
B6: Total revenue | D6: 1500000000 | E6: ARR plus professional services.
B7: Capture adjustment | D7: 1 | E7: Leave at 1.00 unless deliberately scaling every pool.
B8: Reachability curve steepness | D8: 3.5 | E8: Lambda in Barr Eq. 25. Judgemental constant, not calibrated.
B9: Vendor AI only? (Yes / No) | D9: No | E9: Barr caps Phi at 0.65 where a firm deploys only off-the-shelf vendor AI.
B10: Firm scale factor (Phi) | D10: =IF($D$5=0,1,MIN(1/(1+EXP(-2*LOG10($D$6/$D$5))),1)) -> 0.33518073 | E10: Barr Eq. 21. Logistic on revenue against S*.
B11: Enabler gate | D11: =MIN(1,MIN('2_Capability_Assessment'!$C$80,'2_Capability_Assessment'!$C$81)/7) -> 0.95238095 | E11: Data foundation and governance. Below 7.0 it caps conversion on every lever.
B12: Share of accounts on an AI tier | D12: 0.5 | E12: Sizes Product and services differentiation. Pricing and packaging takes the remainder plus a residual.
B13: Residual pricing headroom on tiered accounts | D13: 0.35 | E13: How much of the 10% discount gap is still open where the AI premium already applies. At 0% the two levers partition the revenue base cleanly.
I14: SCORE | J14: CEILING | L14: REACH | M14: MATURITY | N14: CAPTURE CEILING | O14: ADJUSTED POOL | P14: REV SHARE | Q14: REVENUE EFFECT | R14: COST EFFECT | W14: CASH EBITDA | AE14: METRIC IMPACTED | AF14: UPLIFT SOURCE | AG14: STATUS | AH14: SAAS BAND
B15: Product and services differentiation | C15: =$D$12 -> 0.5 | D15: 0.25 | E15: =$D$6*C15*D15 -> 187500000 | F15: ="GROSS: $"&TEXT($D$6/1000000,"#,##0")&"M x "&TEXT(C15,"0.0%")&" x "&TEXT(D15,"0.0%")&" = $"&TEXT(E15/1000000,"#,##0.0")&"M"&CHAR(10)&"ADJUSTED: x "&TEXT(N15,"0.00")&" capture x "&TEXT(L15,"0.000")&" reach x "&TEXT(M15,"0.000")&" maturity = $"&TEXT(O15/1000000,"#,##0.0")&"M" -> GROSS: $1,500M x 50.0% x 25.0% = $187.5M ADJUSTED: x 0.80 capture x 0.725 reach x 0.600 maturity = $21.9M | G15: Accounts on an AI tier, from the shared input above. The AI premium lifts revenue per account by 25%. Company figure. | I15: ='2_Capability_Assessment'!$C$46 -> 5.9882353 | J15: ='2_Capability_Assessment'!$D$46 -> 9.5 | L15: =MAX(0.15,1-EXP(-$D$8*'2_Capability_Assessment'!$C$70/10)) -> 0.72535895 | M15: =IFERROR(I15/J15,0)*$D$11 -> 0.60032434 | N15: 0.8 | O15: =E15*N15*L15*M15*$D$7*$D$10 -> 21893199 | P15: 1 | Q15: =O15*P15 -> 21893199 | R15: =O15*(1-P15) -> 0 | V15: 1 | W15: =R15*V15 -> 0 | X15: =R15*(1-V15) -> 0 | Z15: ='7_Value_Timing'!$C$25 -> 0.95977741 | AA15: =IFERROR(Z15,"") -> 0.95977741 | AB15: =O15*AA15*'5_Implementation_Feasibility'!$E$13 -> 19168732 | AE15: ARR growth, NRR | AF15: SaaS-specific. AI-native SaaS enables pricing models that were not viable before — per-AI-query billing, premium AI tiers and MCP access fees for partners wanting structured data access (Qrvey, 2026). No published median for the premium itself, so 25% remains a Contoso figure. | AG15: COMPANY | AH15: —
B16: Pricing and packaging | C16: =(1-$D$12)+$D$12*$D$13 -> 0.675 | D16: 0.1 | E16: =$D$6*C16*D16 -> 1.0125e+08 | F16: ="GROSS: $"&TEXT($D$6/1000000,"#,##0")&"M x "&TEXT(C16,"0.0%")&" x "&TEXT(D16,"0.0%")&" = $"&TEXT(E16/1000000,"#,##0.0")&"M"&CHAR(10)&"ADJUSTED: x "&TEXT(N16,"0.00")&" capture x "&TEXT(L16,"0.000")&" reach x "&TEXT(M16,"0.000")&" maturity = $"&TEXT(O16/1000000,"#,##0.0")&"M" -> GROSS: $1,500M x 67.5% x 10.0% = $101.3M ADJUSTED: x 0.50 capture x 0.725 reach x 0.574 maturity = $7.1M | G16: Accounts not on an AI tier carry the full 10% discount gap. Accounts already on a tier have had part of that gap closed by the premium, so only the residual share below applies to them. This is what stops Pricing and Product double-counting the same dollar. | I16: ='2_Capability_Assessment'!$C$47 -> 5.7 | J16: ='2_Capability_Assessment'!$D$47 -> 9.45 | L16: =MAX(0.15,1-EXP(-$D$8*'2_Capability_Assessment'!$C$70/10)) -> 0.72535895 | M16: =IFERROR(I16/J16,0)*$D$11 -> 0.574452 | N16: 0.5 | O16: =E16*N16*L16*M16*$D$7*$D$10 -> 7070511 | P16: 0.55 | Q16: =O16*P16 -> 3888781 | R16: =O16*(1-P16) -> 3181729.9 | V16: 1 | W16: =R16*V16 -> 3181729.9 | X16: =R16*(1-V16) -> 0 | Z16: ='7_Value_Timing'!$C$25 -> 0.95977741 | AA16: =IFERROR(Z16,"") -> 0.95977741 | AB16: =O16*AA16*'5_Implementation_Feasibility'!$E$13 -> 6190631.4 | AE16: ASP, realised price, NRR | AF16: SaaS-specific. Per-seat pricing is breaking as customers reduce seats rather than add them; Workday attributed an 8.5% workforce reduction to AI efficiency. Hybrid models are the bridge. The 10% realised discount is a Contoso figure. | AG16: COMPANY | AH16: —
B17: Sales effectiveness | C17: 0.184 | D17: 0.15 | E17: =$D$6*C17*D17 -> 41400000 | F17: ="GROSS: $"&TEXT($D$6/1000000,"#,##0")&"M x "&TEXT(C17,"0.0%")&" x "&TEXT(D17,"0.0%")&" = $"&TEXT(E17/1000000,"#,##0.0")&"M"&CHAR(10)&"ADJUSTED: x "&TEXT(N17,"0.00")&" capture x "&TEXT(L17,"0.000")&" reach x "&TEXT(M17,"0.000")&" maturity = $"&TEXT(O17/1000000,"#,##0.0")&"M" -> GROSS: $1,500M x 18.4% x 15.0% = $41.4M ADJUSTED: x 0.70 capture x 0.725 reach x 0.555 maturity = $3.9M | G17: Sales 15% plus marketing 8% of ARR, the 2026 SaaS Capital medians, converted to 18.4% of total revenue. Fifteen percent of that comes back. Split 40% to revenue won and 60% to cost saved — AI selling capacity can be taken as fewer sellers or as more pipeline. | I17: ='2_Capability_Assessment'!$C$48 -> 5.5555556 | J17: ='2_Capability_Assessment'!$D$48 -> 9.525 | L17: =MAX(0.15,1-EXP(-$D$8*'2_Capability_Assessment'!$C$70/10)) -> 0.72535895 | M17: =IFERROR(I17/J17,0)*$D$11 -> 0.55548612 | N17: 0.7 | O17: =E17*N17*L17*M17*$D$7*$D$10 -> 3913844.9 | P17: 0.4 | Q17: =O17*P17 -> 1565538 | R17: =O17*(1-P17) -> 2348306.9 | V17: 1 | W17: =R17*V17 -> 2348306.9 | X17: =R17*(1-V17) -> 0 | Z17: ='7_Value_Timing'!$C$25 -> 0.95977741 | AA17: =IFERROR(Z17,"") -> 0.95977741 | AB17: =O17*AA17*'5_Implementation_Feasibility'!$E$13 -> 3426792.1 | AE17: Win rate, sales efficiency | AF17: SaaS-specific. State of B2B SaaS Sales 2026, 500+ companies: firms that rebuilt the SDR motion around AI see 3–5x better results than those running 2020-era manual prospecting. Cross-industry anchor: Brynjolfsson, Li and Raymond, QJE 2025, 14% average productivity gain across 5,179 agents. | AG17: PUBLISHED | AH17: 15–25%
B18: Customer retention and expansion | C18: 1 | D18: 0.019 | E18: =$D$6*C18*D18 -> 28500000 | F18: ="GROSS: $"&TEXT($D$6/1000000,"#,##0")&"M x "&TEXT(C18,"0.0%")&" x "&TEXT(D18,"0.0%")&" = $"&TEXT(E18/1000000,"#,##0.0")&"M"&CHAR(10)&"ADJUSTED: x "&TEXT(N18,"0.00")&" capture x "&TEXT(L18,"0.000")&" reach x "&TEXT(M18,"0.000")&" maturity = $"&TEXT(O18/1000000,"#,##0.0")&"M" -> GROSS: $1,500M x 100.0% x 1.9% = $28.5M ADJUSTED: x 0.60 capture x 0.725 reach x 0.625 maturity = $2.6M | G18: AI churn prediction moves SaaS churn from 6.8% to 4.9% after twelve months — 1.9 points of revenue retained. | I18: ='2_Capability_Assessment'!$C$49 -> 6.0352941 | J18: ='2_Capability_Assessment'!$D$49 -> 9.2 | L18: =MAX(0.15,1-EXP(-$D$8*'2_Capability_Assessment'!$C$70/10)) -> 0.72535895 | M18: =IFERROR(I18/J18,0)*$D$11 -> 0.62477165 | N18: 0.6 | O18: =E18*N18*L18*M18*$D$7*$D$10 -> 2597463.4 | P18: 0.6 | Q18: =O18*P18 -> 1558478 | R18: =O18*(1-P18) -> 1038985.4 | V18: 1 | W18: =R18*V18 -> 1038985.4 | X18: =R18*(1-V18) -> 0 | Z18: ='7_Value_Timing'!$C$25 -> 0.95977741 | AA18: =IFERROR(Z18,"") -> 0.95977741 | AB18: =O18*AA18*'5_Implementation_Feasibility'!$E$13 -> 2274225.8 | AE18: GRR, NRR | AF18: SaaS-specific. AI resolves 50–60% of tier-1 support queries and reduces customer service costs by roughly 30% (industry reporting, 2026). Churn falls from 6.8% to 4.9% after twelve months of AI churn prediction — 1.9 points of revenue retained. | AG18: PUBLISHED | AH18: —
B19: Ecosystem strategy | C19: 0.3 | D19: 0.02 | E19: =$D$6*C19*D19 -> 9000000 | F19: ="GROSS: $"&TEXT($D$6/1000000,"#,##0")&"M x "&TEXT(C19,"0.0%")&" x "&TEXT(D19,"0.0%")&" = $"&TEXT(E19/1000000,"#,##0.0")&"M"&CHAR(10)&"ADJUSTED: x "&TEXT(N19,"0.00")&" capture x "&TEXT(L19,"0.000")&" reach x "&TEXT(M19,"0.000")&" maturity = $"&TEXT(O19/1000000,"#,##0.0")&"M" -> GROSS: $1,500M x 30.0% x 2.0% = $9.0M ADJUSTED: x 0.45 capture x 0.725 reach x 0.539 maturity = $0.5M | G19: 30% of revenue comes through partners. AI lifts that by 2%. Company figure. | I19: ='2_Capability_Assessment'!$C$50 -> 5.2769231 | J19: ='2_Capability_Assessment'!$D$50 -> 9.325 | L19: =MAX(0.15,1-EXP(-$D$8*'2_Capability_Assessment'!$C$70/10)) -> 0.72535895 | M19: =IFERROR(I19/J19,0)*$D$11 -> 0.53894274 | N19: 0.45 | O19: =E19*N19*L19*M19*$D$7*$D$10 -> 530676.26 | P19: 1 | Q19: =O19*P19 -> 530676.26 | R19: =O19*(1-P19) -> 0 | V19: 1 | W19: =R19*V19 -> 0 | X19: =R19*(1-V19) -> 0 | Z19: ='7_Value_Timing'!$C$25 -> 0.95977741 | AA19: =IFERROR(Z19,"") -> 0.95977741 | AB19: =O19*AA19*'5_Implementation_Feasibility'!$E$13 -> 464637.02 | AE19: Partner-sourced ARR, CAC | AF19: SaaS-specific but thin. MCP access fees for partners wanting structured data access are an emerging revenue line (Qrvey, 2026). No published uplift figure. 2% is judgemental. | AG19: UNSOURCED | AH19: —
B20: Product engineering | C20: 0.176 | D20: 0.26 | E20: =$D$6*C20*D20 -> 68640000 | F20: ="GROSS: $"&TEXT($D$6/1000000,"#,##0")&"M x "&TEXT(C20,"0.0%")&" x "&TEXT(D20,"0.0%")&" = $"&TEXT(E20/1000000,"#,##0.0")&"M"&CHAR(10)&"ADJUSTED: x "&TEXT(N20,"0.00")&" capture x "&TEXT(L20,"0.000")&" reach x "&TEXT(M20,"0.000")&" maturity = $"&TEXT(O20/1000000,"#,##0.0")&"M" -> GROSS: $1,500M x 17.6% x 26.0% = $68.6M ADJUSTED: x 0.85 capture x 0.725 reach x 0.725 maturity = $10.3M | G20: R&D at the 2026 median of 22% of ARR, converted to 17.6% of total revenue. AI makes engineers 26% faster. | I20: ='2_Capability_Assessment'!$C$51 -> 7.1529412 | J20: ='2_Capability_Assessment'!$D$51 -> 9.4 | L20: =MAX(0.15,1-EXP(-$D$8*'2_Capability_Assessment'!$C$70/10)) -> 0.72535895 | M20: =IFERROR(I20/J20,0)*$D$11 -> 0.72471542 | N20: 0.85 | O20: =E20*N20*L20*M20*$D$7*$D$10 -> 10280062 | P20: 0 | Q20: =O20*P20 -> 0 | R20: =O20*(1-P20) -> 10280062 | V20: 1 | W20: =R20*V20 -> 10280062 | X20: =R20*(1-V20) -> 0 | Z20: ='7_Value_Timing'!$C$25 -> 0.95977741 | AA20: =IFERROR(Z20,"") -> 0.95977741 | AB20: =O20*AA20*'5_Implementation_Feasibility'!$E$13 -> 9000774.2 | AE20: R&D as % of revenue | AF20: SaaS-specific. GitHub reports its AI coding assistant automates roughly 30% of developers’ code writing. Cross-industry RCT: Cui et al. 2025, 4,867 developers at Microsoft, Accenture and a Fortune 100 firm, 26.08% more completed pull requests. | AG20: PUBLISHED | AH20: 26–30%
B21: Revenue operations | C21: 0.024 | D21: 0.3 | E21: =$D$6*C21*D21 -> 10800000 | F21: ="GROSS: $"&TEXT($D$6/1000000,"#,##0")&"M x "&TEXT(C21,"0.0%")&" x "&TEXT(D21,"0.0%")&" = $"&TEXT(E21/1000000,"#,##0.0")&"M"&CHAR(10)&"ADJUSTED: x "&TEXT(N21,"0.00")&" capture x "&TEXT(L21,"0.000")&" reach x "&TEXT(M21,"0.000")&" maturity = $"&TEXT(O21/1000000,"#,##0.0")&"M" -> GROSS: $1,500M x 2.4% x 30.0% = $10.8M ADJUSTED: x 0.65 capture x 0.725 reach x 0.622 maturity = $1.1M | G21: 3% of ARR, the revops share of the 15% G&A benchmark, converted to 2.4% of revenue. Quote-to-cash automation removes 30% of it. | I21: ='2_Capability_Assessment'!$C$52 -> 6.0714286 | J21: ='2_Capability_Assessment'!$D$52 -> 9.3 | L21: =MAX(0.15,1-EXP(-$D$8*'2_Capability_Assessment'!$C$70/10)) -> 0.72535895 | M21: =IFERROR(I21/J21,0)*$D$11 -> 0.62175408 | N21: 0.65 | O21: =E21*N21*L21*M21*$D$7*$D$10 -> 1061176.9 | P21: 0.2 | Q21: =O21*P21 -> 212235.37 | R21: =O21*(1-P21) -> 848941.49 | V21: 1 | W21: =R21*V21 -> 848941.49 | X21: =R21*(1-V21) -> 0 | Z21: ='7_Value_Timing'!$C$25 -> 0.95977741 | AA21: =IFERROR(Z21,"") -> 0.95977741 | AB21: =O21*AA21*'5_Implementation_Feasibility'!$E$13 -> 929120.23 | AE21: Sales cycle time, G&A as % of revenue | AF21: SaaS-specific. EvenFlow AI, an automotive scheduling SaaS, reduced operational capacity inefficiencies by up to 30% automating workflows that previously required manual analysis. Single case, not a median. | AG21: PARTIAL | AH21: ~30%
B22: Supplier and infrastructure cost | C22: 0.072 | D22: 0.15 | E22: =$D$6*C22*D22 -> 16200000 | F22: ="GROSS: $"&TEXT($D$6/1000000,"#,##0")&"M x "&TEXT(C22,"0.0%")&" x "&TEXT(D22,"0.0%")&" = $"&TEXT(E22/1000000,"#,##0.0")&"M"&CHAR(10)&"ADJUSTED: x "&TEXT(N22,"0.00")&" capture x "&TEXT(L22,"0.000")&" reach x "&TEXT(M22,"0.000")&" maturity = $"&TEXT(O22/1000000,"#,##0.0")&"M" -> GROSS: $1,500M x 7.2% x 15.0% = $16.2M ADJUSTED: x 0.20 capture x 0.725 reach x 0.357 maturity = $0.3M | G22: Hosting 5% plus DevOps 4% of ARR at the 2026 medians, converted to 7.2% of revenue. Cut 15% by buying better and routing inference by cost. | I22: ='2_Capability_Assessment'!$C$53 -> 3.3866667 | J22: ='2_Capability_Assessment'!$D$53 -> 9.025 | L22: =MAX(0.15,1-EXP(-$D$8*'2_Capability_Assessment'!$C$70/10)) -> 0.72535895 | M22: =IFERROR(I22/J22,0)*$D$11 -> 0.35738469 | N22: 0.2 | O22: =E22*N22*L22*M22*$D$7*$D$10 -> 281522.41 | P22: 0 | Q22: =O22*P22 -> 0 | R22: =O22*(1-P22) -> 281522.41 | V22: 1 | W22: =R22*V22 -> 281522.41 | X22: =R22*(1-V22) -> 0 | Z22: ='7_Value_Timing'!$C$25 -> 0.95977741 | AA22: =IFERROR(Z22,"") -> 0.95977741 | AB22: =O22*AA22*'5_Implementation_Feasibility'!$E$13 -> 246488.76 | AE22: Gross margin, COGS per transaction | AF22: SaaS-specific and pointing the other way. Scaling AI to production routinely reveals 500–1,000% cost underestimation; companies underestimate total AI cost by 30% or more (Herbatschek, 2026). Inference, storage, fine-tuning and in-production maintenance compound. Treat 15% as optimistic. | AG22: CONTESTED | AH22: negative risk
B23: Employee experience | C23: 0.096 | D23: 0.15 | E23: =$D$6*C23*D23 -> 21600000 | F23: ="GROSS: $"&TEXT($D$6/1000000,"#,##0")&"M x "&TEXT(C23,"0.0%")&" x "&TEXT(D23,"0.0%")&" = $"&TEXT(E23/1000000,"#,##0.0")&"M"&CHAR(10)&"ADJUSTED: x "&TEXT(N23,"0.00")&" capture x "&TEXT(L23,"0.000")&" reach x "&TEXT(M23,"0.000")&" maturity = $"&TEXT(O23/1000000,"#,##0.0")&"M" -> GROSS: $1,500M x 9.6% x 15.0% = $21.6M ADJUSTED: x 0.70 capture x 0.725 reach x 0.544 maturity = $2.0M | G23: The remaining 12% of the G&A benchmark, converted to 9.6% of revenue. Back office works 15% faster. | I23: ='2_Capability_Assessment'!$C$54 -> 5.26875 | J23: ='2_Capability_Assessment'!$D$54 -> 9.225 | L23: =MAX(0.15,1-EXP(-$D$8*'2_Capability_Assessment'!$C$70/10)) -> 0.72535895 | M23: =IFERROR(I23/J23,0)*$D$11 -> 0.54394115 | N23: 0.7 | O23: =E23*N23*L23*M23*$D$7*$D$10 -> 1999565.9 | P23: 0 | Q23: =O23*P23 -> 0 | R23: =O23*(1-P23) -> 1999565.9 | V23: 1 | W23: =R23*V23 -> 1999565.9 | X23: =R23*(1-V23) -> 0 | Z23: ='7_Value_Timing'!$C$25 -> 0.95977741 | AA23: =IFERROR(Z23,"") -> 0.95977741 | AB23: =O23*AA23*'5_Implementation_Feasibility'!$E$13 -> 1750732.8 | AE23: G&A as % of revenue | AF23: SaaS-specific. Companies consolidating their SaaS stack see 20–35% cost reductions and 3.2x ROI within twelve months; platform AI now replaces 25–35% of point solutions out of the box. AI point tools have the lowest utilisation of any category at 38%. | AG23: PUBLISHED | AH23: 20–35%
B24: Capital efficiency | C24: 0 | D24: 0 | E24: =$D$6*C24*D24 -> 0 | F24: ="GROSS: $"&TEXT($D$6/1000000,"#,##0")&"M x "&TEXT(C24,"0.0%")&" x "&TEXT(D24,"0.0%")&" = $"&TEXT(E24/1000000,"#,##0.0")&"M"&CHAR(10)&"ADJUSTED: x "&TEXT(N24,"0.00")&" capture x "&TEXT(L24,"0.000")&" reach x "&TEXT(M24,"0.000")&" maturity = $"&TEXT(O24/1000000,"#,##0.0")&"M" -> GROSS: $1,500M x 0.0% x 0.0% = $0.0M ADJUSTED: x 0.00 capture x 0.725 reach x 0.502 maturity = $0.0M | G24: No independent pool. CAC payback and cost to serve are realisations of the other levers — sizing them here would double-count Sales effectiveness and Employee experience. | I24: ='2_Capability_Assessment'!$C$55 -> 4.8357143 | J24: ='2_Capability_Assessment'!$D$55 -> 9.175 | L24: =MAX(0.15,1-EXP(-$D$8*'2_Capability_Assessment'!$C$70/10)) -> 0.72535895 | M24: =IFERROR(I24/J24,0)*$D$11 -> 0.50195555 | N24: 0 | O24: =E24*N24*L24*M24*$D$7*$D$10 -> 0 | P24: 0 | Q24: =O24*P24 -> 0 | R24: =O24*(1-P24) -> 0 | V24: 1 | W24: =R24*V24 -> 0 | X24: =R24*(1-V24) -> 0 | Z24: ='7_Value_Timing'!$C$25 -> 0.95977741 | AA24: =IFERROR(Z24,"") -> 0.95977741 | AB24: =O24*AA24*'5_Implementation_Feasibility'!$E$13 -> 0 | AE24: Rule of 40, CAC payback | AF24: Not sized. CAC payback and cost to serve are realisations of the other levers; a pool here would double-count. | AG24: N/A | AH24: —
B25: TOTAL | E25: =SUM(E15:E24) -> 484890000 | O25: =SUM(O15:O24) -> 49628021 | Q25: =SUM(Q15:Q24) -> 29648908 | R25: =SUM(R15:R24) -> 19979114 | W25: =SUM(W15:W24) -> 19979114 | X25: =SUM(X15:X24) -> 0
B27: SUMMARY — read by the downstream tabs
B28: Gross pool | E28: =E25 -> 484890000
B29: Adjusted pool at current capability | E29: =O25 -> 49628021
B30: Share of gross captured | E30: =IFERROR(O25/E25,0) -> 0.10234903
B31: Left on the table | E31: =E25-O25 -> 4.3526198e+08
B32: Revenue effect | E32: =Q25 -> 29648908
B33: Cost effect | E33: =R25 -> 19979114
B34: Cash EBITDA effect | E34: =W25 -> 19979114
B35: Largest adjusted pool | E35: =INDEX($B$15:$B$24,MATCH(MAX($O$15:$O$24),$O$15:$O$24,0)) -> Product and services differentiation
B36: Aggregate capture check | E36: =SUMPRODUCT($N$15:$N$24,$L$15:$L$24,$M$15:$M$24) -> 2.3545855
B37: Adjusted pool after feasibility | E37: =O25*'5_Implementation_Feasibility'!$E$13 -> 45273137
B38: Realised in window, timed | E38: =SUM(AB15:AB24) -> 43452134
B39: Lost to timing | E39: =O25*'5_Implementation_Feasibility'!$E$13-$E$38 -> 1821003
B40: Revenue effect, timed | E40: =SUMPRODUCT($Q$15:$Q$24,$AA$15:$AA$24)*'5_Implementation_Feasibility'!$E$13 -> 25959292
B41: Cash EBITDA effect, timed | E41: =SUMPRODUCT($W$15:$W$24,$AA$15:$AA$24)*'5_Implementation_Feasibility'!$E$13 -> 17492842
...

Sheet 4d_Metric_Impact
B2: Metric impact
B3: Each operating metric starts from a stated baseline. The value pools that feed it are converted into an uplift and a target. Pools here are after feasibility and timing — the run rate a sponsor can underwrite, not the gross prize.
B5: INPUTS
B6: ARR | C6: 1200000000
B7: Total revenue | C7: ='4b_Value_Pools_by_Capability'!$D$6 -> 1500000000
B10: METRIC | C10: BASELINE | D10: UPLIFT | E10: TARGET | F10: POOL BEHIND THIS METRIC | G10: SHARE OF THE DISTINCT POOL | H10: HOW IT CONVERTS
